<?xml version="1.0" ?>
<!-- =================================================================================== -->
<!-- |    This document was autogenerated by xacro from amr_base.xacro                 | -->
<!-- |    EDITING THIS FILE BY HAND IS NOT RECOMMENDED                                 | -->
<!-- =================================================================================== -->
<robot name="amr_base">
  <!--************* ROBOT'S FOOTPRINT **************-->
  <link name="base_footprint"/>
  <joint name="base_to_base" type="fixed">
    <parent link="base_footprint"/>
    <child link="base_link"/>
    <origin rpy="0 0 0" xyz="0 0 0"/>
  </joint>
  <!--************* ROBOT'S BASE **************-->
  <link name="base_link">
    <visual>
      <geometry>
        <mesh filename="package://amr_desc/meshes/amr_base.dae"/>
      </geometry>
      <origin rpy="0 0 1.5707963267948966" xyz="0 0 0.033"/>
      <material name="metal">
        <color rgba="0.8 0.8 0.8 1"/>
      </material>
    </visual>
    <collision>
      <origin rpy="0 0 0" xyz="0 0 0.1625"/>
      <geometry>
        <cylinder length="0.255" radius="0.23"/>
      </geometry>
    </collision>
    <inertial>
      <origin rpy="1.5707963267948966 0 0" xyz="0 0 0"/>
      <mass value="40000.0"/>
      <inertia ixx="745.7500000000001" ixy="0" ixz="0" iyy="745.7500000000001" iyz="0" izz="1058.0"/>
    </inertial>
  </link>
  <link name="lwheel_link">
    <visual>
      <origin rpy="1.5707963267948966 0 0" xyz="0 0 0"/>
      <geometry>
        <mesh filename="package://amr_desc/meshes/amr_wheel.dae"/>
      </geometry>
      <material name="black">
        <color rgba="0 0 0 1"/>
      </material>
    </visual>
    <collision>
      <origin rpy="0 0 0" xyz="0 0 0"/>
      <geometry>
        <cylinder length="0.0435" radius="0.0825"/>
      </geometry>
    </collision>
  </link>
  <joint name="lwheel_joint" type="revolute">
    <parent link="base_link"/>
    <child link="lwheel_link"/>
    <origin rpy="-1.5707963267948966 0 0" xyz="0 0.1825 0.0825"/>
    <limit effort="30" lower="-3.1415" upper="3.1415" velocity="5.0"/>
    <axis xyz="0 0 1"/>
  </joint>
  <link name="rwheel_link">
    <visual>
      <origin rpy="1.5707963267948966 0 0" xyz="0 0 0"/>
      <geometry>
        <mesh filename="package://amr_desc/meshes/amr_wheel.dae"/>
      </geometry>
      <material name="black">
        <color rgba="0 0 0 1"/>
      </material>
    </visual>
    <collision>
      <origin rpy="0 0 0" xyz="0 0 0"/>
      <geometry>
        <cylinder length="0.0435" radius="0.0825"/>
      </geometry>
    </collision>
  </link>
  <joint name="rwheel_joint" type="revolute">
    <parent link="base_link"/>
    <child link="rwheel_link"/>
    <origin rpy="1.5707963267948966 0 0" xyz="0 -0.1825 0.0825"/>
    <limit effort="30" lower="-3.1415" upper="3.1415" velocity="5.0"/>
    <axis xyz="0 0 -1"/>
  </joint>
  <link name="fcaster_link">
    <visual>
      <geometry>
        <mesh filename="package://amr_desc/meshes/amr_caster.dae"/>
      </geometry>
      <origin rpy="0 0 1.5707963267948966" xyz="0 0 0"/>
      <material name="white">
        <color rgba="1 1 1 1"/>
      </material>
    </visual>
    <collision>
      <origin rpy="0 0 0" xyz="0 0 0.04125"/>
      <geometry>
        <sphere radius="0.054"/>
      </geometry>
    </collision>
    <inertial>
      <mass value="10.05"/>
      <inertia ixx="0.01172232" ixy="0.0" ixz="0.0" iyy="0.01172232" iyz="0.0" izz="0.01172232"/>
    </inertial>
  </link>
  <joint name="fcaster_joint" type="fixed">
    <parent link="base_link"/>
    <child link="fcaster_link"/>
    <origin rpy="0 0 0" xyz="0.135 0 0"/>
  </joint>
  <link name="lcaster_link">
    <visual>
      <geometry>
        <mesh filename="package://amr_desc/meshes/amr_caster.dae"/>
      </geometry>
      <origin rpy="0 0 1.5707963267948966" xyz="0 0 0"/>
      <material name="white">
        <color rgba="1 1 1 1"/>
      </material>
    </visual>
    <collision>
      <origin rpy="0 0 0" xyz="0 0 0.04125"/>
      <geometry>
        <sphere radius="0.054"/>
      </geometry>
    </collision>
    <inertial>
      <mass value="10.05"/>
      <inertia ixx="0.01172232" ixy="0.0" ixz="0.0" iyy="0.01172232" iyz="0.0" izz="0.01172232"/>
    </inertial>
  </link>
  <joint name="lcaster_joint" type="fixed">
    <parent link="base_link"/>
    <child link="lcaster_link"/>
    <origin rpy="0 0 0" xyz="-0.135 0.105 0"/>
  </joint>
  <link name="rcaster_link">
    <visual>
      <geometry>
        <mesh filename="package://amr_desc/meshes/amr_caster.dae"/>
      </geometry>
      <origin rpy="0 0 1.5707963267948966" xyz="0 0 0"/>
      <material name="white">
        <color rgba="1 1 1 1"/>
      </material>
    </visual>
    <collision>
      <origin rpy="0 0 0" xyz="0 0 0.04125"/>
      <geometry>
        <sphere radius="0.054"/>
      </geometry>
    </collision>
    <inertial>
      <mass value="10.05"/>
      <inertia ixx="0.01172232" ixy="0.0" ixz="0.0" iyy="0.01172232" iyz="0.0" izz="0.01172232"/>
    </inertial>
  </link>
  <joint name="rcaster_joint" type="fixed">
    <parent link="base_link"/>
    <child link="rcaster_link"/>
    <origin rpy="0 0 0" xyz="-0.135 -0.105 0"/>
  </joint>
  <!--************* ROBOT'S LASER **************-->
  <link name="laser">
    <visual>
      <geometry>
        <cylinder length="0.04" radius="0.02"/>
      </geometry>
      <origin rpy="0 0 0" xyz="0 0 0.0"/>
      <material name="black">
        <color rgba="0 0 0 1"/>
      </material>
    </visual>
  </link>
  <joint name="base_to_scanner" type="fixed">
    <parent link="base_link"/>
    <child link="laser"/>
    <origin rpy="0 0 0" xyz="0.165 0 0.24"/>
  </joint>
  <!--************* ROBOT'S CAMERA **************-->
  <link name="camera_link">
    <visual>
      <geometry>
        <mesh filename="package://amr_desc/meshes/d435.dae"/>
      </geometry>
      <origin rpy="1.5707963267948966 0 1.5707963267948966" xyz="0 0 0"/>
      <material name="black">
        <color rgba="0 0 0 1"/>
      </material>
    </visual>
  </link>
  <joint name="base_to_camera" type="fixed">
    <parent link="base_link"/>
    <child link="camera_link"/>
    <origin rpy="0 0 0" xyz="0.23 0 0.15"/>
  </joint>
  <link name="imu_link"/>
  <joint name="imu_joint" type="fixed">
    <parent link="camera_link"/>
    <child link="imu_link"/>
    <origin rpy="0 0 0" xyz="0 0 0"/>
  </joint>
</robot>
